# 第一章 异常

异常，就是不正常的意思。在生活中：医生说，你的身体某个部位有异常，该部位和正常相比有点不同，该部位的功能将受到影响。在程序中的意思是：

* **异常**：指的是程序在执行过程中，出现的非正常的情况，最终会导致JVM的非正常停止。

在Java等面向对象的编程语言中，异常本身是一个类，产生异常就是创建异常并抛出一个异常对象。Java处理异常的方式是中断处理。

> 异常指的并不是语法错误，语法错了，编译不通过，不会产生字节码文件，根本不能运行。

## 1.1 异常体系

异常机制其实就是帮助我们找到程序中的问题，异常的根类是`java.lang.Throwable` ，其下有两个子类：`java.lang.Error`与`java.lang.Exception`，平常所说的异常指`java.lang.Exception`。 

<!-- throw 投; 掷; 抛; 扔; 摔; 丢; 猛推; 使劲撞; able 能够的; 能; 能够；--> 

<!-- exception 例外 -->

<!-- expect 预料 期待 期望-->

![](D:\Java\笔记\图片\1-05【异常、单元测试】\1异常分类.png)

**Throwable体系：**

* **Error**：严重错误Error，无法通过处理的错误，只能事先避免，好比绝症。Error类代表了编译和系统的错误，不允许捕获；
* **Exception**：表示异常，异常产生后程序员可以通过代码的方式修正，使程序继续执行，是必须要处理的。好比感冒、阑尾炎。Exception类代表了标准Java库方法所激发的异常。Exception类还包含运行异常类Runtime_Exception和非运行异常类Non_RuntimeException这两个直接的子类。

**Throwable中的常用方法：**

* `public void printStackTrace()`：打印异常的详细信息。

  包含了异常的类型，异常的原因，还包括异常出现的位置，在开发和调试阶段，都得使用printStackTrace。

* `public String getMessage()`：获取发生异常的原因。

  提示给用户的时候，就提示错误原因。

* `public String toString()`：获取异常的类型和异常描述信息(不用)。

出现异常，不要紧张，把异常的简单类型名，拷贝到API中去查。

## 1.2 异常Exception

我们平常说的异常就是指Exception，因为这类异常一旦出现，我们就要对代码进行更正，修复程序。

![](D:\Java\笔记\图片\1-05【异常、单元测试】\1异常分类.png)

**异常(Exception)的分类**：

* **运行时期异常**：runtime异常，又称为非受检查异常。不受检查！不受检查！！不受检查！！！因为不受检查，所以在代码中可能会有RunTimeException时Java编译检查时不会告诉你有这个异常，但是在实际运行代码时则会暴露出来，比如经典的1/0，空指针等。如果不处理也会被Java自己处理。
* **非运行时异常**：非运行异常时Non_RuntimeException类及其子类的实例，又称为可检测异常，受检查异常，编译期异常。Java编译器利用分析方法或构造方法中可能产生的结果来检测Java程序中是否含有检测异常的处理程序，对于每个可能的可检测异常，方法或构造方法的throws子句必须列出该异常对应的类。在Java的标准包java.lang java.util 和Java net中定义的异常都是非运行异常。IOException、classNotFund

**代码如下：**

```java
public class Demo01Exception {
    public static void main(String[] args) throws ParseException {
        // Exception:编译时期异常，进行编译（写代码）java程序出现的问题
        SimpleDateFormat sdf = new SimpleDateFormat("yyy-MM-dd");// 用来格式化日期
        // 出现异常，使用抛出异常的方式
        Date date = sdf.parse("1999-09-09");// 把字符串格式的日期，解析为Date格式的日期。
        System.out.println(date);
    }
}
```

```java
public class Demo01Exception {
    public static void main(String[] args) {
        // Exception:编译时期异常，进行编译（写代码）java程序出现的问题
        SimpleDateFormat sdf = new SimpleDateFormat("yyy-MM-dd");// 用来格式化日期
        // 出现异常，使用try-catch方式
        Date date = null;
        try {
            date = sdf.parse("1999-09-09");// 把字符串格式的日期，解析为Date格式的日期。
        } catch (ParseException e) {
            e.printStackTrace();
        }
        System.out.println(date);
    }
}
```

```java
public class Demo01Exception {
    public static void main(String[] args) {
        // RuntimeException:运行期异常，java程序运行过程中出现的问题
        int[] arr = {1, 2, 3};
        System.out.println(arr[0]);

        try {
            // 可能会出现异常的代码
            System.out.println(arr[3]);
        } catch(Exception e) {
            // 异常的处理逻辑
            System.out.println(e);
        }
        System.out.println("后续代码");
    }
}

```

```java
public class Demo01Exception {
    public static void main(String[] args) {
        /*
            Error:错误
            OutOfMemoryError：java heap space
            内存溢出的错误，创建的数组太大了，超过了给JVM分配的内存
         */
        // int[] arr = new int[1024 * 1024 * 1024];// 必须修改代码，创建的数组小一点
        int[] arr = new int[1024 * 1024];
        System.out.println("后续代码");

    }
}
```

## 1.3 常见的异常

| 异常类型                       | 说明                                           |
| ------------------------------ | ---------------------------------------------- |
| RuntimeException               | 运行时异常，多数 java.lang 异常的根类          |
| IOException                    | I/O 异常，文件未找到、未打开或者IO操作不能进行 |
| ArithmeticException            | 算数异常，例如零做除数                         |
| ArrayIndexOutOfBoundsException | 数组越界索引异常                               |
| NullPointerException           | 空指针异常                                     |
| ClassNotFoundException         | 无法加载指定的类异常                           |
| ClassCastException             | 强制转换类异常                                 |
| IllegalArgumentException       | 不合法的参数异常                               |
| FileNotFoundException          | 文件找不到异常                                 |
| EOFException                   | 文件已结束异常                                 |
| SQLException                   | 操作数据库异常                                 |
| InterruptedException           | 线程终端异常                                   |

## 1.4 异常产生过程

运行下面的程序，程序会产生一个数组索引越界异常`ArrayIndexOfBoundsException`。

![异常的产生过程解析](..\图片\1-05【异常、单元测试】\1-1.4 异常的产生过程解析.png)

## 1.5 中断、异常与陷入

中断/异常/陷入机制是操作系统由用户态转为内核态的唯一途径，是操作系统的驱动力。

### 1.5.1 中断与异常

中断、异常机制有以下特征：随机发生、自动处理（硬件完成）、可恢复。终端和异常是CPU对系统发生的某个事情做出的一种反应。

中断、异常的区别：

- 中断属外部事件，是正在运行的程序所不期望的
- 异常由正在执行的指令引发

中断/异常的引入目的：

- 中断的引入是为了CPU与设备之间的并行操作
- 异常的引入是为了表示CPU执行指令时本身出现的问题

一个故事：小明在看书，突然来了个电话，接完电话继续看书，这是中断；小明在看书，感觉口渴了，喝了水接着看书，这是异常。

<table>
<thead>
  <tr>
    <th></th>
    <th>类别</th>
    <th>原因</th>
    <th>同步/异步</th>
    <th>返回行为</th>
  </tr>
</thead>
<tbody>
  <tr>
    <td>中断</td>
    <td>中断（interrupt）</td>
    <td>来自I/O设备或其他硬件部件</td>
    <td>异步</td>
    <td>总是返回到下一条指令</td>
  </tr>
  <tr>
    <td rowspan="3">异常</td>
    <td>陷入(trap)</td>
    <td>有意识安排的</td>
    <td>同步</td>
    <td>返回到下一条指令</td>
  </tr>
  <tr>
    <td>故障（fault）</td>
    <td>可恢复的错误</td>
    <td>同步</td>
    <td>返回到当前指令</td>
  </tr>
  <tr>
    <td>终止（abort）</td>
    <td>不可恢复的错误</td>
    <td>同步</td>
    <td>不会返回</td>
  </tr>
</tbody>
</table>

* 中断：中断是指 CPU 对系统发生某事件时的这样一种响应:

  CPU 暂停正在执行的程序，在保留现场后自动地转去执行该事件的中断处理程序；执行完后，再返回到原程序的断点处继续执行。

* 异常：异常是由当前正在执行的进程产生。

  异常包括很多方面，有出错（fault），有陷入（trap），也有可编程异常（programmable exception）。

### 1.5.2 中断与陷入

- 外中断——就是我们指的中断——是指由于外部设备事件所引起的中断，如通常的磁盘中断、打印机中断等；
- 内中断——就是异常——是指由于 CPU 内部事件所引起的中断，如程序出错(非法指令、地址越界)溢出、除数为零等。内中断(trap)也被译为“捕获”或“陷入”。

![](..\图片\1-05【异常、单元测试】\3-事件.png)

# 第二章 异常的处理

Java异常处理的五个关键字：try、catch、finally、throw、throws

## 2.1 抛出异常throw

在编写程序的时候，我们必须要考虑程序出现的问题的情况。比如，在定义方法时，方法需要接受参数。那么，当调用方法使用接收到的参数时，首先需要先对参数数据进行合法的判断，数据若不合法，就应该告诉调用者，传递合法的数据进来。这时需要使用抛出异常的方式来告诉调用者。

在Java中，提供了一个**throw**关键字，它用来抛出一个指定的异常对象。那么，抛出一个异常具体如何操作呢？

1. 创建一个异常对象。封装一些提示信息（信息可以自己编写）。

2. 需要将这个异常对象告知给调用者。怎么告知呢？怎么将这个异常对象传递到调用者处呢？通过关键字throw就可以完成。throw异常对象。

   throw用在方法内，用来抛出一个异常对象，将这个异常对象传递到调用者处，并结束当前方法的执行。

之前学习过一个类Objects，它由一些静态的实用方法组成，这些方法是null-save（空指针安全的）或者null-tolerant（容忍空指针的），那么在它的源码中，对对象为null的值进行了抛出异常操作。

* `public static <T> T requireNonNull(T obj)`:查看指定引用对象不是null。

查看源码发现这里对为null的进行了抛出异常操作：

```java
public static <T> T requireNOnNUll(T Obj) {
    if (obj == null)
        throw new NullPointerException();
    return obj;
}
```

```java
public class Demo04Objects {
    public static void main(String[] args) {
        method(null);
    }

    public static void method(Object obj) {
        Objects.requireNonNull(obj, "传递的对象的值是null");
    }
}
```

## 2.3 声明异常throws

**声明异常**：将问题标识出来，报告给调用者，如果方法内通过throw抛出了编译时异常，而没有捕获处理，那么必须通过throws进行声明，让调用者去处理。

关键字throws运用于方法声明之上，用于表示当前方法不处理异常，而是提醒该方法的调用者来处理异常（抛出异常）。异常声明格式：`修饰符 返回值类型 方法名(参数) throws 异常类名1，异常类名2...{    }`

throws关键字：异常处理的第一种方式，交给别人来处理

作用：

* 当方法内部抛出异常对象的时候，那么我们就必须处理这个异常对象
* 可以使用throws关键字处理异常对象，会把异常对象声明抛出给方法的调用者处理（自己不处理，给别人处理），最终转交给JVM处理-->中断处理

注意：

* throws关键字必须写在方法声明处

* throws关键字后边声明的异常必须是Exception或者是Exception的子类

* 方法内部如果跑出了多个异常对象，那么throws后边必须也声明多个异常。如果抛出的多个异常对象有子父类关系，那么直接声明父类异常即可

* 调用一个声明抛出异常的方法，我们就必须处理声明的异常，要么继续使用throws声明抛出，交给方法的调用者处理，最终给JVM；要么try...catch自己处理异常。


```java
public class Demo05Throws {

    public static void main(String[] args) throws IOException {
        readFile("c:\\a.txt");
    }

    // FileNotFoundException是编译异常，抛出了编译异常，就必须处理这个异常
    // IOException是FileNotFoundException父类，所以只需抛出IOException
    public static void readFile(String fileName) throws IOException {
        if (!fileName.equals("c:\\a.txt")) {
            throw new FileNotFoundException("传递的文件路径不是c:\\a.txt");
        }

        if (!fileName.endsWith(".txt")) {
            throw new IOException("文件名的后缀不对");
        }

        System.out.println("路径没有问题，读取文件");
    }
}
```

## 2.4 捕获异常try...catch

如果异常出现的话，会立刻终止程序，所以我们得处理异常：

1. 该方法不处理，而是声明抛出，由该方法的调用者来处理(throws)。
2. 在方法中使用try-catch的语句块来处理异常。

**try-catch**的方式就是捕获异常。**捕获异常**：java中对异常有针对性的语句进行捕获，可以对出现的异常进行指定方式的处理。

捕获异常语法如下：`try...catch`

```java
/*
    try {
        可能产生异常的代码
    } catch(定义一个异常的变量，用来接收try中抛出的异常对象) {
        异常的处理逻辑，异常对象之后，怎么处理异常对象
        一般在工作中，会把异常的信息记录到一个日志中
    }
    ...
    catch(异常类名 变量名) {

    }
*/
```

注意：

1. try中可能会抛出多个异常对象，那么就可以使用多个catch来处理这些异常对象

2. 如果try中产生了异常，那么就会执行catch中的异常处理逻辑，执行完毕catch中的处理逻辑，继续执行try...catch之后的代码

   如果try中没有产生异常，那么就不会执行catch中异常的处理逻辑，执行完try中的代码，继续执行try...catch之后的代码

```java
public class Demo01TryCatch {
    public static void main(String[] args) {
        try {
            // 可能产生异常的代码
            // d:\\a.txt和d:\\a.tx的结果是不一样的
            readFile("d:\\a.txt");
        } catch (IOException e) {
            // try中抛出什么异常对象，catch就定义什么异常变量，用来接收这个异常对象
            // 异常的处理逻辑，异常对象之后，怎么处理异常对象
            System.out.println("传递的文件不是.txt");
        }
        System.out.println("后续代码");
    }

    public static void readFile(String fileName) throws IOException {
        if (!fileName.endsWith(".txt")) {
            throw new IOException("文件名的后缀不对");
        }
        System.out.println("路径没有问题，读取文件");
    }
}
```

如何获取异常信息，Throwable类中定义了一些查看方法：

* `public String getMessage`():获取异常的描述信息，原因（提示给用户的时候，就提示错误原因）。

* `public String toString`():获取异常的类型和异常描述信息。

* `public void printStackTrace`():打印异常的跟踪栈信息并输出到控制台。

  包含了异常的类型，异常的原因，还包括异常出现的位置，在开发和调试的阶段，都得使用printStackTrace。

```java
public class Demo01TryCatch {
    public static void main(String[] args) {
        try {
            // 可能产生异常的代码
            // d:\\a.txt和d:\\a.tx的结果是不一样的
            readFile("d:\\a.tx");
        } catch (IOException e) {
            System.out.println(e.getMessage()); // 文件名的后缀不对
            System.out.println(e.toString()); // 重写Object类的toString方法  java.io.IOException: 文件名的后缀不对
            System.out.println(e); // java.io.IOException: 文件名的后缀不对

            /*
                java.io.IOException: 文件名的后缀不对
                    at cn.demo02.Demo01TryCatch.readFile(Demo01TryCatch.java:36)
                    at cn.demo02.Demo01TryCatch.main(Demo01TryCatch.java:10)
             */
            e.printStackTrace();

        }
        System.out.println("后续代码");
    }

    public static void readFile(String fileName) throws IOException {
        if (!fileName.endsWith(".txt")) {
            throw new IOException("文件名的后缀不对");
        }
        System.out.println("路径没有问题，读取文件");
    }
}
```

在开发中也可以在catch将编译器异常转化成运行期异常处理。

多个异常使用捕获又该如何处理呢？

1. 多个异常分别处理。
2. 多个异常一次捕获，多次处理。
3. 多个异常一次捕获一次处理。

## 2.4 finally代码块

**finally**：有一些特定的代码无论异常是否发生，都需要执行。另外，因为异常会引发程序跳转，导致有些语句执行不到。而finally就是解决这个问题的，在finally代码块中存放的代码都是一定会被执行的。

当我们在try语句块中打开了一些物理资源(磁盘文件/网络连接/数据库连接等)，我们都得在使用完之后，最终关闭打开的资源。比如在我们之后学习的IO流中，当打开了一个关联文件的资源，最后程序不管结果如何，都需要把这个资源关闭掉。

finally的语法：`try...catch...finally`。finally不能单独使用。

finally代码参考如下：

```java
/*
    try {
        可能产生异常的代码
    } catch(定义一个异常的变量，用来接收try中抛出的异常对象) {
        异常的处理逻辑，异常对象之后，怎么处理异常对象
        一般在工作中，会把异常的信息记录到一个日志中
    }
    ...
    catch(异常类名 变量名) {

    }finally {
        无论是否出现异常都会执行
    }
    注意：
        1.finally不能单独使用，必须和try一起使用
        2.finally一般用于资源释放(资源回收)，无论程序是否出现异常，最后都要资源释放(IO)
*/
```

```java
public class Demo02TryCatchFinally {

    public static void main(String[] args) {
        try {
            readFile("c:\\a.txt");
        } catch (IOException e) {
            e.printStackTrace();
        } finally {
            System.out.println("资源释放");
        }
    }

    public static void readFile(String fileName) throws IOException {
        if (!fileName.endsWith(".txt")) {
            throw new IOException("文件名的后缀不对");
        }
        System.out.println("路径没有问题，读取文件");
    }
}
```

### 2.4.1 finally中的return

```java
public class Demo3 {
	public static void main(String[] args) {
		int i = Demo3.test();
        //结果为20
		System.out.println(i);
	}

	public static int test() {
		int i;
		try {
			i = 10;
			return i;
		} finally {
			i = 20;
			return i;
		}
	}
}
```

```java
Code:
     stack=1, locals=3, args_size=0
        0: bipush        10
        2: istore_0
        3: iload_0
        4: istore_1 				 //暂存返回值
        5: bipush        20
        7: istore_0
        8: iload_0
        9: ireturn					//ireturn会返回操作数栈顶的整型值20
       10: astore_2					//如果出现异常，还是会执行finally块中的内容，没有抛出异常
       11: bipush        20
       13: istore_0
       14: iload_0
       15: ireturn					//这里没有athrow了
     Exception table:
        from    to  target type
            0     5    10   anyCopy
```

- 由于 ﬁnally 中的 ireturn 被插入了所有可能的流程，因此返回结果肯定以ﬁnally的为准
- 至于字节码中第 2 行，似乎没啥用，且留个伏笔，看下个例子
- 跟上例中的 ﬁnally 相比，发现没有 athrow 了，这告诉我们：如果在 ﬁnally 中出现了 return，会吞掉异常
- 所以不要在finally中进行返回操作

例如下面的操作会吞掉异常：

```java
public class Demo3 {
   public static void main(String[] args) {
      int i = Demo3.test();
      //最终结果为20
      System.out.println(i);
   }

   public static int test() {
      int i;
      try {
         i = 10;
         i = i/0;			//这里应该会抛出异常 但是并没有
         return i;
      } finally {
         i = 20;
         return i;
      }
   }
}
```

会发现打印结果为20，并未抛出异常

### 2.4.2 finally不带return

```java
public class Demo4 {
	public static void main(String[] args) {
		int i = Demo4.test();
		System.out.println(i);	// i = 10
	}

	public static int test() {
		int i = 10;
		try {
			return i;
		} finally {
			i = 20;
		}
	}
}
```

```java
Code:
     stack=1, locals=3, args_size=0
        0: bipush        10
        2: istore_0 						// 赋值给i 10
        3: iload_0							// 加载到操作数栈顶
        4: istore_1 						// 加载到局部变量表的1号位置
        5: bipush        20
        7: istore_0 						// 赋值给i 20
        8: iload_1							// 加载局部变量表1号位置的数10到操作数栈
        9: ireturn 							// 返回操作数栈顶元素 10
       10: astore_2
       11: bipush        20
       13: istore_0
       14: aload_2 							// 加载异常
       15: athrow 							// 抛出异常
     Exception table:
        from    to  target type
            3     5    10   anyCopy
```

## 2.5 try with resource

### 2.5.1 JDK7特性

`JDK 7` 开始新增了对需要关闭的资源处理的特殊语法 `try-with-resources`：

```java
try(资源变量 = 创建资源对象){
    
} catch( ) {
    
}
```

其中资源对象需要实现 `AutoCloseable` 接口，例如 `InputStream` 、 `OutputStream` 、`Connection` 、 `Statement` 、 `ResultSet` 等接口都实现了 `AutoCloseable` ，使用 `try-withresources` 可以不用写 finally 语句块，编译器会帮助生成关闭资源代码，例如：

```java
public class Demo01 {
    public static void main(String[] args) {
        try(InputStream is = new FileInputStream("d:\\1.txt")) {
            System.out.println(is);
        } catch (IOException e) {
            e.printStackTrace();
        }
    }
}
```

会被转换为：

```java
public class Demo01 {
    public Demo01() {
    }
    
    public static void main(String[] args) {
        try {
            InputStream is = new FileInputStream("d:\\1.txt");
            Throwable t = null;
            try {
                System.out.println(is);
            } catch (Throwable e1) {
                // t 是我们代码出现的异常
                t = e1;
                throw e1;
            } finally {
                // 判断了资源不为空
                if (is != null) {
                    // 如果我们代码有异常
                    if (t != null) {
                        try {
                            is.close();
                        } catch (Throwable e2) {
                            // 如果 close 出现异常，作为被压制异常添加
                            t.addSuppressed(e2);
                        }
                    } else {
                        // 如果我们代码没有异常，close 出现的异常就是最后 catch 块中的 e
                        is.close();
                    }
                }
            }
        } catch (IOException e) {
            e.printStackTrace();
        }
    }
}
```

为什么要设计一个 `addSuppressed(Throwable e)` （添加被压制异常）的方法呢？是为了防止异常信息的丢失（想想 try-with-resources 生成的 fianlly 中如果抛出了异常）：

```java
public class Test6 {
    public static void main(String[] args) {
        try (MyResource resource = new MyResource()) {
            int i = 1/0;
        } catch (Exception e) {
            e.printStackTrace();
        }
    }
}
class MyResource implements AutoCloseable {
    public void close() throws Exception {
        throw new Exception("close 异常");
    }
}
```

输出：

```apl
java.lang.ArithmeticException: / by zero
    at test.Test6.main(Test6.java:7)
    Suppressed: java.lang.Exception: close 异常
        at test.MyResource.close(Test6.java:18)
        at test.Test6.main(Test6.java:6)
```

如以上代码所示，两个异常信息都不会丢。

### 2.5.2 JDK9特性

JDK9的新特性：

* try前面定义流对象。

* try后面的()中可以直接引入对象的名称(变量名)。

* try代码执行完毕后，流对象可以释放掉，不用写finally。

* 定义流对象的时候有异常要抛出处理。


格式如下：

```java
A a = new A();
B b = new B();

try(a；b) {
    可能会产生异常的代码
} catch(异常类变量 变量名) {
    异常的处理逻辑
}
```

```java
public class Demo03JDK9 {
    public static void main(String[] args) throws FileNotFoundException {
        // 1.创建一个字节输入流对象，构造方法中绑定要读取的数据源
        FileInputStream fis = new FileInputStream("D:\\图片\\18.jpg");
        // 2.创建一个字节输出流对象，构造方法中绑定写入的目的地
        FileOutputStream fos = new FileOutputStream("D:\\Java\\19.jpg");

        try (fis; fos) {
            // 3.使用字节输入流对象中的方法read读取文件
            // 4.使用字节输出流中的方法write，把读取到的字节写入到目的地文件中
            int len = 0;
            while((len = fis.read()) != -1) {
                fos.write(len);
            }
        } catch (IOException e) {
            System.out.println(e);
        }
    }
}
```

## 2.6 异常注意事项

运行时异常被抛出可以不处理。即不捕获也不声明抛出。

### 2.6.1 多个异常捕获

多个异常使用捕获又该如何处理呢？

1. 多个异常分别处理。
2. 多个异常一次捕获，多次处理。
3. 多个异常一次捕获一次处理。

一般我们时使用一次捕获多次处理方式，格式如下：

```java
try {
    编写可能会出现异常的代码
} catch(异常类型A e) { // 当try中出现A类型异常，就用该catch来捕获。
    处理异常的代码 	// 记录日志/打印异常信息/继续抛出异常
} catch(异常类型B e) { // 当try中出现B类型异常，就用该catch来捕获。
    处理异常的代码 	// 记录日志/打印异常信息/继续抛出异常
}
```

> 注意：这种异常处理方式，要求多个catch中的异常不能相同，并且若catch中的多个异常之间有子父类异常的关系，那么子类异常要求在上面的catch处理，父类异常在下面的catch处理。

```java
public class Demo01Exception {
    public static void main(String[] args) {

        // 1.多个异常分别处理。
        try {
            int[] arr = {1, 2, 3};
            // ArrayIndexOutOfBoundsException: Index 3 out of bounds for length 3
            System.out.println(arr[3]);
        } catch (ArrayIndexOutOfBoundsException e) {
            System.out.println(e);
        }

        try {
            List<Integer> list = List.of(1, 2, 3);
            // IndexOutOfBoundsException :Index 3 out of bounds for length 3
            System.out.println(list.get(3));
        } catch (ArrayIndexOutOfBoundsException e) {
            System.out.println(e);
        }
    }
}
```

```java
public class Demo01Exception {
    public static void main(String[] args) {

        // 2.多个异常一次捕获，多次处理
        /*
            一个try多个catch注意事项：
                catch里面定义的异常变量，如果有子父类关系，那么子类的异常必须写在上面，否则就会报错
                ArrayIndexOutOfBoundsException extends IndexOutOfBoundsException
         */
        try {
            int[] arr = {1, 2, 3};
            // ArrayIndexOutOfBoundsException: Index 3 out of bounds for length 3
            System.out.println(arr[3]);
            List<Integer> list = List.of(1, 2, 3);
            // IndexOutOfBoundsException :Index 3 out of bounds for length 3
            System.out.println(list.get(3));
        } catch (ArrayIndexOutOfBoundsException e) {
            System.out.println(e);
        } catch (IndexOutOfBoundsException e) {
            System.out.println(e);
        }
    }
}
```

```java
public class Demo01Exception {
    public static void main(String[] args) {
        // 3.多个异常一次捕获一次处理
        try {
            int[] arr = {1, 2, 3};
            // ArrayIndexOutOfBoundsException: Index 3 out of bounds for length 3
            System.out.println(arr[3]);
            List<Integer> list = List.of(1, 2, 3);
            // IndexOutOfBoundsException :Index 3 out of bounds for length 3
            System.out.println(list.get(3));
        } catch (Exception e) {
            System.out.println(e);
        }
        System.out.println("后续代码！");
    }
}
```

### 2.6.3 子类继承父类异常

* 如果父类抛出了多个异常，子类重写父类方法时，抛出和父类相同的异常或者是父类异常的子集或者不抛出异常。
* 父类方法没有抛出异常，子类重写父类该方法时也不可抛出异常。此时子类产生该异常，只能捕获处理，不能声明抛出
* 父类异常什么样子，子类异常就是什么样子

```java
public class Fu {
    public void show01() throws NullPointerException, ClassCastException{}
    public void show02() throws IndexOutOfBoundsException{}
    public void show03() throws IndexOutOfBoundsException{}
    public void show04() {}
}
```

```java
class Zi extends Fu {
    // 子类重写父类方法时，抛出和父类相同的异常
    public void show01() throws NullPointerException, ClassCastException{}
    // 子类重写父类方法时，抛出父类异常的子集
    public void show02() throws ArrayIndexOutOfBoundsException{}
    // 子类重写父类方法时，不抛出异常
    public void show03() {}

    /*
        父类方法没有抛出异常，子类重写父类该方法时也不可抛出异常。
        此时子类产生该异常，只能捕获处理，不能声明抛出
     */
    public void show04() {
        try {
            throw new Exception("编译期异常");
        } catch (Exception e) {
            e.printStackTrace();
        }
    }
}
```

# 第三章 自定义异常

为什么需要自定义异常类：我们说了java中不同的异常类，分别表示着某一种具体的异常情况，那么在开发中总是有些异常情况是JDK没有定义好的，此时我们根据自己业务的异常情况来定义异常类。例如年龄负数问题，考试成绩负数问题等等。

什么是自定义异常类：在开发中根据自己业务的异常情况来定义异常类。

异常类如何定义：

1. 自定义一个编译期异常：自定义类并继承`java.lang.Exception`。
2. 自定义一个运行时期的异常类：自定义类并继承`java.lang.RuntimeException`。

格式如下：

```java
public class XXXException extends Exception / RuntimeException {
    添加一个空参数的构造方法
    添加一个带异常信息的构造方法
}
```

1. 自定义异常类一般都是以Exception结尾，说明该类是一个异常类

2. 自定义异常类，必须的继承Exception或者RuntimeException

   继承`Exception`：继承了Exception也就是定义为受检查异常，则需要在使用者进行处理的。那么自定义异常类就是一个编译期异常，如果方法内部抛出了编译期异常，就必须处理这个异常，要么throws，要么try...catch

   继承`RuntimeException`：那么自定义的异常类就是一个运行期异常，无需处理，交给虚拟机处理（中断处理）

下面来联系一下自定义异常类：自定义一个业务逻辑异常：**RegisterException**。一个注册异常类。

```java
public class RegisterException extends Exception{
    // 添加一个空参数的构造方法
    public RegisterException() {
        super();
    }

    // 所有异常类都有一个带异常信息的构造方法 该方法内部调用父类带异常信息的构造方法 让父类来处理这个异常信息
    public RegisterException(String message) {
        super(message);
    }
}
```

```java
public class Demo01 {
	// 1.使用数组保存已经注册过的用户名
	static String[] usernames = { "张三", "李四", "王五" };

	public static void main(String[] args) {
		// 2.使用Scanner获取用户输入的注册的用户名
		Scanner sc = new Scanner(System.in);
		System.out.println("请输入您要注册的用户名");
		String username = sc.next();
		checkUsername(username);
		sc.close();
	}

	// 3.定义一个方法，对用户输入的注册的用户名进行判断
	public static void checkUsername(String username)  {
		// 遍历存储已经注册过用户名的数组，获取每一个用户名
		for (String name : usernames) {
			// 使用获取到的用户名和用户输入的用户名进行比较
			if (name.equals(username)) {
				// true:用户名已存在，抛出RegisterException异常，告知用户“亲，该用户名已经被注册了”；
				try {
					throw new RegisterException("亲，该用户名已经被注册了");
				} catch (RegisterException e) {
					e.printStackTrace();
					return;
				}
			}
		}

		// 循环结束，没有找到重复的用户名，提示用户“恭喜您，注册成功！”;
		System.out.println("恭喜您，注册成功！");
	}
}
```

# 第四章 Junit单元测试

测试分类：

1. 黑盒测试：不需要写代码，给输入值，看看程序是否能够输出期望的值。
2. 白盒测试：需要写代码，关注程序具体的执行流程。(Junit单元测试就是白盒测试)。

![](D:\Java\笔记\图片\1-05【异常、单元测试】\4Junit.png)

使用方法如下：

1. 定义一个测试类（测试用例）
   * 测试类名命名规则：被测试的类名 + Test `CalculatorTest`
   * 包名命名规则：XXX.XXX.XXX.test  `com.linxuan.test`
2. 在测试类里面定义测试方法（测试方法可以独立运行，点击旁边的绿色小三角即可）
   * 方法名命名规则：test + 测试的方法名 `testAdd()`
   * 返回值：void
   * 参数列表：空参

   * 测试方法要使用public修饰
3. 给测试方法加上注解`@Test`
4. 导入Junit依赖环境
5. 运行测试方法，检查判定结果（测试方法可以独立运行，点击旁边的绿色小三角即可）

## 4.1 判定结果

* 红色：失败

* 绿色：成功

* 一般我们会使用断言操作来处理结果

  Assert.assertEquals(期望的结果，result);

  如果结果与我们期望的结果不同，会抛出异常，变成红色。

```java
// 被测试类
public class Calculator {
    public int add(int a, int b) {
        return a + b;
    }

    public int sub(int a, int b) {
        return a - b;
    }
}
```

```java
// 定义测试类
public class CalculatorTest {

    // 定义测试方法 加上注解@Test
    @Test
    public void testAdd() {
        // 创建对象，使用对象的方法
        Calculator c = new Calculator();
        int result = c.add(1, 2);

        // 断言操作
        Assert.assertEquals(3, result);
    }

    @Test
    public void testSub() {
        // 创建对象，使用对象的方法
        Calculator c = new Calculator();
        int result = c.sub(1, 2);

        // 断言操作
        // 期待的值与结果不一样，会变成红色，报错
        Assert.assertEquals(3, result);
    }
}
```

## 4.2 补充注解

当我们在测试的时候会有很多重复的操作，例如IO流中的获取资源和释放资源。每当测试一个方法就需要重复操作。有注解可以帮助我们。

* `@Before`：
  * 修饰的成员方法会在测试之前被自动执行
  * 初始化方法：用于资源申请，所有测试方法在执行之前都会先执行该方法
* `@After`：
  * 修饰的成员方法会在测试方法执行之后自动被执行
  * 释放资源方法：在所有测试方法执行完成之后，都会自动执行该方法

`@After`注解的方法没有必要放在最后，两者放在前面就可以了，最后会自动执行这个注解的方法的。

```java
@Before
public void init() {
    System.out.println("init...");
}

@After
public void close() {
    System.out.println("close...");
}
```
